Workbook
Name IQ_CH: 110000
Name IQ_CQ: 5000
Name IQ_CY: 10000
Name IQ_DAILY: 500000
Name IQ_FH: 100000
Name IQ_FQ: 500
Name IQ_FY: 1000
Name IQ_LTM: 2000
Name IQ_MONTH: 15000
Name IQ_NTM: 6000
Name IQ_WEEK: 50000
Name IQ_YTD: 3000
Name UPDATE: 'Data Sheet'!$E$1

Sheet DCF
A2: # | B2: Calculation of PV of FCFF | C2: ='Intrisic Growth'!K2 -> 46082 | D2: =C2+366 -> 46448 | E2: =D2+366 -> 46814 | F2: =E2+366 -> 47180 | G2: =F2+366 -> 47546 | H2: =G2+366 -> 47912
B4: EBIT | C4: ='Data Sheet'!K34-'Data Sheet'!K26 -> 2483.9 | D4: =C4*(1+$C$13) -> 3198.0534 | E4: =D4*(1+$C$13) -> 4117.5351 | F4: =E4*(1+$C$13) -> 5301.3796 | G4: =F4*(1+$C$13) -> 6825.5948 | H4: =G4*(1+$C$13) -> 8788.0416
B5: Tax Rate | C5: 0.25 | D5: =C5 -> 0.25 | E5: =D5 -> 0.25 | F5: =E5 -> 0.25 | G5: =F5 -> 0.25 | H5: =G5 -> 0.25
B6: EBIT (1-T) | C6: =C4*(1-C5) -> 1862.925 | D6: =D4*(1-D5) -> 2398.54 | E6: =E4*(1-E5) -> 3088.1513 | F6: =F4*(1-F5) -> 3976.0347 | G6: =G4*(1-G5) -> 5119.1961 | H6: =H4*(1-H5) -> 6591.0312
B7: Less Reinvestment Rate | C7: ='Intrisic Growth'!K52 -> 0.69188049 | D7: =C7 -> 0.69188049 | E7: =D7 -> 0.69188049 | F7: =E7 -> 0.69188049 | G7: =F7 -> 0.69188049 | H7: =G7 -> 0.69188049
B8: Free Cash Flow to Firm | C8: =C6*(1-C7) -> 574.00354 | D8: =D6*(1-D7) -> 739.03699 | E8: =E6*(1-E7) -> 951.51967 | F8: =F6*(1-F7) -> 1225.0939 | G8: =G6*(1-G7) -> 1577.3242 | H8: =H6*(1-H7) -> 2030.8253
B9: Mid Year Convention | D9: 0.5 | E9: =D9+1 -> 1.5 | F9: =E9+1 -> 2.5 | G9: =F9+1 -> 3.5 | H9: =G9+1 -> 4.5
B10: Discounting Factor | D10: =1/(1+$C$15)^D9 -> 0.93245033 | E10: =1/(1+$C$15)^E9 -> 0.81073165 | F10: =1/(1+$C$15)^F9 -> 0.70490168 | G10: =1/(1+$C$15)^G9 -> 0.61288637 | H10: =1/(1+$C$15)^H9 -> 0.5328824
B11: PV of FCFF | D11: =D8*D10 -> 689.11528 | E11: =E8*E10 -> 771.42711 | F11: =F8*F10 -> 863.57073 | G11: =G8*G10 -> 966.72051 | H11: =H8*H10 -> 1082.1911
A13: # | B13: Expected Growth | C13: ='Intrisic Growth'!K62 -> 0.28751293
B14: Terminal Growth | C14: 0.0538 | D14: long term gdp growth rate
B15: WACC | C15: =WACC!J33 -> 0.15013437
A17: # | B17: Calculation of Terminal Value | E17: Sensitivity Analysis
E18: =C35 -> 1097.6532 | F18: =G18-2% -> 0.11013437 | G18: =H18-2% -> 0.13013437 | H18: =C15 -> 0.15013437 | I18: =H18+2% -> 0.17013437 | J18: =I18+2% -> 0.19013437
B19: FCFF (n+1) | C19: =H8*(1+C14) -> 2140.0837 | E19: =E20-2% -> 0.0138 | F19: 1097.6532 | G19: 968.42094 | H19: 877.10497 | I19: 809.15327 | J19: 756.61585
B20: WACC | C20: =C15 -> 0.15013437 | E20: =E21-2% -> 0.0338 | F20: 1294.6044 | G20: 1097.6532 | H20: 968.42094 | I20: 877.10497 | J20: 809.15327
B21: Terminal Growth Rate | C21: =C14 -> 0.0538 | E21: =C14 -> 0.0538 | F21: 1631.4001 | G21: 1294.6044 | H21: 1097.6532 | I21: 968.42094 | J21: 877.10497
B22: Terminal Value | C22: =C19/(C20-C21) -> 22215.162 | E22: =E21+2% -> 0.0738 | F22: 2338.9695 | G22: 1631.4001 | H22: 1294.6044 | I22: 1097.6532 | J22: 968.42094
E23: =E22+2% -> 0.0938 | F23: 4779.2517 | G23: 2338.9695 | H23: 1631.4001 | I23: 1294.6044 | J23: 1097.6532
A24: # | B24: Calculation of Equity Value per Share
B26: PV of FCFF | C26: =SUM(D11:H11) -> 4373.0247
B27: PV of Terminal Value | C27: =C22*H10 -> 11838.069
B28: Value of Operating Assets | C28: =SUM(C26:C27) -> 16211.094
B30: Add: Cash | C30: ='Data Sheet'!K69 -> 1218.25
B31: Less: Debt | C31: =SUM('Raw FS'!N7:N8) -> 143.24
B32: Value of Equity | C32: =C28+C30-C31 -> 17286.104
B33: No of Shares | C33: ='Data Sheet'!B6 -> 15.748238
A35: # | B35: Equity Value per Share | C35: =C32/C33 -> 1097.6532
B36: current live Share price | C36: ='Raw Beta Peers'!D6 -> 5654
B37: Discount/Premium | C37: =C36/C35 -> 5.1509895

Sheet WACC
B2: Weighted Average Cost of Capital
B4: Peer Companies
G5: Debt/ | H5: Debt/ | I5: Levered | J5: Unlevered
B6: Name | C6: Country | D6: Total Debt | E6: Total Equity | F6: Tax Rate | G6: Equity | H6: Capital | I6: Beta | J6: Beta
B7: ='Raw Beta Peers'!C4 -> LTM | C7: India | D7: ='Raw Beta Peers'!F4 -> 2310 | E7: ='Raw Beta Peers'!E4 -> 131820.63 | F7: 0.3 | G7: =D7/E7 -> 0.017523812 | H7: =D7/(D7+E7) -> 0.017222017 | I7: ='Raw Beta Peers'!H4 -> 1.16 | J7: =I7/(1+(1-F7)*G7) -> 1.1459431
B8: ='Raw Beta Peers'!C5 -> Oracle Fin. Serv. | C8: India | D8: ='Raw Beta Peers'!F5 -> 32.5 | E8: ='Raw Beta Peers'!E5 -> 103353.1 | F8: 0.3 | G8: =D8/E8 -> 0.00031445598 | H8: =D8/(D8+E8) -> 0.00031435713 | I8: ='Raw Beta Peers'!H5 -> 1.02 | J8: =I8/(1+(1-F8)*G8) -> 1.0197755
B9: ='Raw Beta Peers'!C6 -> Persistent Systems | C9: India | D9: ='Raw Beta Peers'!F6 -> 477.45 | E9: ='Raw Beta Peers'!E6 -> 89040.54 | F9: 0.3 | G9: =D9/E9 -> 0.0053621642 | H9: =D9/(D9+E9) -> 0.0053335648 | I9: ='Raw Beta Peers'!H6 -> 1.09 | J9: =I9/(1+(1-F9)*G9) -> 1.085924
B10: ='Raw Beta Peers'!C7 -> Coforge | C10: India | D10: ='Raw Beta Peers'!F7 -> 727.8 | E10: ='Raw Beta Peers'!E7 -> 84234.62 | F10: 0.3 | G10: =D10/E10 -> 0.0086401529 | H10: =D10/(D10+E10) -> 0.0085661402 | I10: ='Raw Beta Peers'!H7 -> 1.14 | J10: =I10/(1+(1-F10)*G10) -> 1.1331466
B11: ='Raw Beta Peers'!C8 -> Mphasis | C11: India | D11: ='Raw Beta Peers'!F8 -> 2619.68 | E11: ='Raw Beta Peers'!E8 -> 46088.08 | F11: 0.3 | G11: =D11/E11 -> 0.056840728 | H11: =D11/(D11+E11) -> 0.053783627 | I11: ='Raw Beta Peers'!H8 -> 1.32 | J11: =I11/(1+(1-F11)*G11) -> 1.2694889
E13: Average | F13: =AVERAGE(F7:F11) -> 0.3 | G13: =AVERAGE(G7:G11) -> 0.017736263 | H13: =AVERAGE(H7:H11) -> 0.017043941 | I13: =AVERAGE(I7:I11) -> 1.146 | J13: =AVERAGE(J7:J11) -> 1.1308556
E14: Median | F14: =MEDIAN(F7:F11) -> 0.3 | G14: =MEDIAN(G7:G11) -> 0.0086401529 | H14: =MEDIAN(H7:H11) -> 0.0085661402 | I14: =MEDIAN(I7:I11) -> 1.14 | J14: =MEDIAN(J7:J11) -> 1.1331466
B16: Cost of Debt | G16: Cost of Equity
B17: Pre-tax Cost of Debt | E17: 0.075 | G17: Risk Free Rate | J17: 0.0685
B18: Tax Rate | E18: =F14 -> 0.3 | G18: Equity Risk Premium | J18: =Rm!G7-WACC!J17 -> 0.061003341
B19: After Tax Cost of Debt | E19: =E17*(1-E18) -> 0.0525 | G19: Levered Beta | J19: =J26 -> 1.4494581
G20: Cost of Equity | J20: =J17+(J18*J19) -> 0.15692179
B22: Capital Structure | G22: Levered Beta
D23: Current | E23: Target | G23: Comps Median Unlevered Beta | J23: =J14 -> 1.1331466
B24: Total Debt | C24: =D9 -> 477.45 | D24: =C24/$C$26 -> 0.0053335648 | E24: 0.065 | G24: Target Debt/ Equity | J24: =E28 -> 0.069518717
B25: Market Capitalization | C25: =E9 -> 89040.54 | D25: =C25/$C$26 -> 0.99466644 | E25: =E26-E24 -> 0.935 | G25: Tax Rate | J25: =E18 -> 0.3
B26: Total Capitalization | C26: =SUM(C24:C25) -> 89517.99 | D26: =C26/$C$26 -> 1 | E26: =D26 -> 1 | G26: Levered Beta | J26: =J23*(1+(1-J24)*J25) -> 1.4494581
B28: Debt / Equity | D28: =D24/D25 -> 0.0053621642 | E28: =E24/E25 -> 0.069518717 | G28: Weighted Average Cost of Capital
G29: Cost of Equity | J29: =J20 -> 0.15692179
G30: Equity Weight | J30: =E25 -> 0.935
G31: Cost of Debt | J31: =E19 -> 0.0525
G32: Debt Weight | J32: =E24 -> 0.065
G33: WACC | J33: =(J29*J30)+(J31*J32) -> 0.15013437

Sheet Rm
B2: Return on Markets
F3: source-primeinvestor
B4: Year | C4: Annual | D4: 1+Return
B5: 2000 | C5: -0.1465 | D5: =1+C5 -> 0.8535 | E5: Average Return | G5: =GEOMEAN(D5:D30)-1 -> 0.11650334
B6: 2001 | C6: -0.1618 | D6: =1+C6 -> 0.8382 | E6: Dividend Yield | G6: 0.013
B7: 2002 | C7: 0.0325 | D7: =1+C7 -> 1.0325 | E7: Total Market Returns | G7: =SUM(G5:G6) -> 0.12950334
B8: 2003 | C8: 0.719 | D8: =1+C8 -> 1.719
B9: 2004 | C9: 0.1068 | D9: =1+C9 -> 1.1068
B10: 2005 | C10: 0.3634 | D10: =1+C10 -> 1.3634
B11: 2006 | C11: 0.3983 | D11: =1+C11 -> 1.3983
B12: 2007 | C12: 0.5477 | D12: =1+C12 -> 1.5477
B13: 2008 | C13: -0.5179 | D13: =1+C13 -> 0.4821
B14: 2009 | C14: 0.7576 | D14: =1+C14 -> 1.7576
B15: 2010 | C15: 0.1795 | D15: =1+C15 -> 1.1795
B16: 2011 | C16: -0.2462 | D16: =1+C16 -> 0.7538
B17: 2012 | C17: 0.277 | D17: =1+C17 -> 1.277
B18: 2013 | C18: 0.0676 | D18: =1+C18 -> 1.0676
B19: 2014 | C19: 0.3139 | D19: =1+C19 -> 1.3139
... B30: 2025 | C30: 0.1051 | D30: =1+C30 -> 1.1051

Sheet Intrisic Growth
A2: # | B2: Calculation of ROIC | F2: ='Raw FS'!I$2 -> 44256 | G2: ='Raw FS'!J$2 -> 44621 | H2: ='Raw FS'!K$2 -> 44986 | I2: ='Raw FS'!L$2 -> 45352 | J2: ='Raw FS'!M$2 -> 45717 | K2: ='Raw FS'!N$2 -> 46082
B3: Current Assets
B4: ='Raw FS'!B35 -> Inventories | F4: ='Raw FS'!I35 -> 0 | G4: ='Raw FS'!J35 -> 0 | H4: ='Raw FS'!K35 -> 0 | I4: ='Raw FS'!L35 -> 0 | J4: ='Raw FS'!M35 -> 0 | K4: ='Raw FS'!N35 -> 0
B5: ='Raw FS'!B36 -> Trade receivables + | F5: ='Raw FS'!I36 -> 570.9 | G5: ='Raw FS'!J36 -> 948.43 | H5: ='Raw FS'!K36 -> 1570.46 | I5: ='Raw FS'!L36 -> 1676.11 | J5: ='Raw FS'!M36 -> 2679.17 | K5: ='Raw FS'!N36 -> 3334.39
B6: ='Raw FS'!B38 -> Loans n Advances | F6: ='Raw FS'!I38 -> 77.4 | G6: ='Raw FS'!J38 -> 131.17 | H6: ='Raw FS'!K38 -> 137.8 | I6: ='Raw FS'!L38 -> 194.99 | J6: ='Raw FS'!M38 -> 170.18 | K6: ='Raw FS'!N38 -> 273.95
B7: ='Raw FS'!B39 -> Other asset items | F7: ='Raw FS'!I39 -> 567.59 | G7: ='Raw FS'!J39 -> 961.89 | H7: ='Raw FS'!K39 -> 1010.57 | I7: ='Raw FS'!L39 -> 1429.89 | J7: ='Raw FS'!M39 -> 1247.97 | K7: ='Raw FS'!N39 -> 2009
B8: Total Current Assets | F8: =SUM(F4:F7) -> 1215.89 | G8: =SUM(G4:G7) -> 2041.49 | H8: =SUM(H4:H7) -> 2718.83 | I8: =SUM(I4:I7) -> 3300.99 | J8: =SUM(J4:J7) -> 4097.32 | K8: =SUM(K4:K7) -> 5617.34
B10: Current Liabilities
B11: ='Raw FS'!B13 -> Trade Payables | F11: ='Raw FS'!I13 -> 293.14 | G11: ='Raw FS'!J13 -> 559.61 | H11: ='Raw FS'!K13 -> 759.51 | I11: ='Raw FS'!L13 -> 758.71 | J11: ='Raw FS'!M13 -> 794.8 | K11: ='Raw FS'!N13 -> 1150.87
B12: ='Raw FS'!B14 -> Advance from Customers | F12: ='Raw FS'!I14 -> 108 | G12: ='Raw FS'!J14 -> 206.17 | H12: ='Raw FS'!K14 -> 279.82 | I12: ='Raw FS'!L14 -> 279.53 | J12: ='Raw FS'!M14 -> 292.82 | K12: ='Raw FS'!N14 -> 424.01
B13: ='Raw FS'!B15 -> Other liability items | F13: ='Raw FS'!I15 -> 370.28 | G13: ='Raw FS'!J15 -> 706.87 | H13: ='Raw FS'!K15 -> 959.38 | I13: ='Raw FS'!L15 -> 958.37 | J13: ='Raw FS'!M15 -> 1003.96 | K13: ='Raw FS'!N15 -> 1453.73
B14: Total Current Liabilities | F14: =SUM(F11:F13) -> 771.42 | G14: =SUM(G11:G13) -> 1472.65 | H14: =SUM(H11:H13) -> 1998.71 | I14: =SUM(I11:I13) -> 1996.61 | J14: =SUM(J11:J13) -> 2091.58 | K14: =SUM(K11:K13) -> 3028.61
A16: # | B16: Net Working Capital | F16: =F8-F14 -> 444.47 | G16: =G8-G14 -> 568.84 | H16: =H8-H14 -> 720.12 | I16: =I8-I14 -> 1304.38 | J16: =J8-J14 -> 2005.74 | K16: =K8-K14 -> 2588.73
B18: Non Current Assets
B19: ='Raw FS'!B19 -> Land | F19: ='Raw FS'!I19 -> 24.92 | G19: ='Raw FS'!J19 -> 83.65 | H19: ='Raw FS'!K19 -> 127.71 | I19: ='Raw FS'!L19 -> 121.17 | J19: ='Raw FS'!M19 -> 138.6 | K19: ='Raw FS'!N19 -> 155.78
B20: ='Raw FS'!B20 -> Building | F20: ='Raw FS'!I20 -> 265.86 | G20: ='Raw FS'!J20 -> 892.26 | H20: ='Raw FS'!K20 -> 1362.23 | I20: ='Raw FS'!L20 -> 1292.49 | J20: ='Raw FS'!M20 -> 1478.45 | K20: ='Raw FS'!N20 -> 1661.66
B21: ='Raw FS'!B21 -> Plant Machinery | F21: ='Raw FS'!I21 -> 232.62 | G21: ='Raw FS'!J21 -> 780.73 | H21: ='Raw FS'!K21 -> 1191.95 | I21: ='Raw FS'!L21 -> 1130.93 | J21: ='Raw FS'!M21 -> 1293.64 | K21: ='Raw FS'!N21 -> 1453.95
B22: ='Raw FS'!B22 -> Equipments | F22: ='Raw FS'!I22 -> 66.46 | G22: ='Raw FS'!J22 -> 223.06 | H22: ='Raw FS'!K22 -> 340.56 | I22: ='Raw FS'!L22 -> 323.12 | J22: ='Raw FS'!M22 -> 369.61 | K22: ='Raw FS'!N22 -> 415.42
B23: ='Raw FS'!B23 -> Furniture n fittings | F23: ='Raw FS'!I23 -> 74.77 | G23: ='Raw FS'!J23 -> 250.95 | H23: ='Raw FS'!K23 -> 383.13 | I23: ='Raw FS'!L23 -> 363.51 | J23: ='Raw FS'!M23 -> 415.81 | K23: ='Raw FS'!N23 -> 467.34
B24: ='Raw FS'!B24 -> Vehicles | F24: ='Raw FS'!I24 -> 8.31 | G24: ='Raw FS'!J24 -> 27.88 | H24: ='Raw FS'!K24 -> 42.57 | I24: ='Raw FS'!L24 -> 40.39 | J24: ='Raw FS'!M24 -> 46.2 | K24: ='Raw FS'!N24 -> 51.93
B25: ='Raw FS'!B25 -> Intangible Assets | F25: ='Raw FS'!I25 -> 99.7 | G25: ='Raw FS'!J25 -> 334.6 | H25: ='Raw FS'!K25 -> 510.84 | I25: ='Raw FS'!L25 -> 484.68 | J25: ='Raw FS'!M25 -> 554.42 | K25: ='Raw FS'!N25 -> 623.12
B26: ='Raw FS'!B26 -> Other fixed assets | F26: ='Raw FS'!I26 -> 58.16 | G26: ='Raw FS'!J26 -> 195.18 | H26: ='Raw FS'!K26 -> 297.99 | I26: ='Raw FS'!L26 -> 282.73 | J26: ='Raw FS'!M26 -> 323.41 | K26: ='Raw FS'!N26 -> 363.49
B28: Gross Block | F28: =SUM(F19:F27) -> 830.8 | G28: =SUM(G19:G27) -> 2788.31 | H28: =SUM(H19:H27) -> 4256.98 | I28: =SUM(I19:I27) -> 4039.02 | J28: =SUM(J19:J27) -> 4620.14 | K28: =SUM(K19:K27) -> 5192.69
B29: Accumulated Depreciation | F29: =-'Raw FS'!I28 -> -373.86 | G29: =-'Raw FS'!J28 -> -1254.74 | H29: =-'Raw FS'!K28 -> -1915.63 | I29: =-'Raw FS'!L28 -> -1817.57 | J29: =-'Raw FS'!M28 -> -2079.07 | K29: =-'Raw FS'!N28 -> -2336.71
A30: # | B30: Net Non Current Assets | F30: =SUM(F28:F29) -> 456.94 | G30: =SUM(G28:G29) -> 1533.57 | H30: =SUM(H28:H29) -> 2341.35 | I30: =SUM(I28:I29) -> 2221.45 | J30: =SUM(J28:J29) -> 2541.07 | K30: =SUM(K28:K29) -> 2855.98
A32: # | B32: Invested Capital | F32: =F30+F16 -> 901.41 | G32: =G30+G16 -> 2102.41 | H32: =H30+H16 -> 3061.47 | I32: =I30+I16 -> 3525.83 | J32: =J30+J16 -> 4546.81 | K32: =K30+K16 -> 5444.71
B33: EBIT | F33: ='Data Sheet'!F34-'Data Sheet'!F26 -> 615.24 | G33: ='Data Sheet'!G34-'Data Sheet'!G26 -> 936.12 | H33: ='Data Sheet'!H34-'Data Sheet'!H26 -> 1288.19 | I33: ='Data Sheet'!I34-'Data Sheet'!I26 -> 1494.33 | J33: ='Data Sheet'!J34-'Data Sheet'!J26 -> 1889.44 | K33: ='Data Sheet'!K34-'Data Sheet'!K26 -> 2483.9
A35: # | B35: ROIC | F35: =F33/F32 -> 0.6825307 | G35: =G33/G32 -> 0.44526044 | H35: =H33/H32 -> 0.42077499 | I35: =I33/I32 -> 0.42382361 | J35: =J33/J32 -> 0.41555288 | K35: =K33/K32 -> 0.45620428
A38: # | B38: Calculation of Reinvestment Rate | F38: ='Raw FS'!I$2 -> 44256 | G38: ='Raw FS'!J$2 -> 44621 | H38: ='Raw FS'!K$2 -> 44986 | I38: ='Raw FS'!L$2 -> 45352 | J38: ='Raw FS'!M$2 -> 45717 | K38: ='Raw FS'!N$2 -> 46082
B40: Net Capex | F40: =-SUM('Raw FS'!I54:I55) -> 291.45 | G40: =-SUM('Raw FS'!J54:J55) -> 524.57 | H40: =-SUM('Raw FS'!K54:K55) -> 206.6 | I40: =-SUM('Raw FS'!L54:L55) -> 283.35 | J40: =-SUM('Raw FS'!M54:M55) -> 279.09 | K40: =-SUM('Raw FS'!N54:N55) -> 333.97
B41: Change in Working Capital | F41: =F16-E16 -> 444.47 | G41: =G16-F16 -> 124.37 | H41: =H16-G16 -> 151.28 | I41: =I16-H16 -> 584.26 | J41: =J16-I16 -> 701.36 | K41: =K16-J16 -> 582.99
B43: EBIT | F43: =F33 -> 615.24 | G43: =G33 -> 936.12 | H43: =H33 -> 1288.19 | I43: =I33 -> 1494.33 | J43: =J33 -> 1889.44 | K43: =K33 -> 2483.9
B44: Marginal Tax Rate | F44: -0.75 | G44: 0.25 | H44: 0.25 | I44: 0.25 | J44: 0.25 | K44: 0.25
B45: EBIT(1-T) | F45: =F43*(1-F44) -> 1076.67 | G45: =G43*(1-G44) -> 702.09 | H45: =H43*(1-H44) -> 966.1425 | I45: =I43*(1-I44) -> 1120.7475 | J45: =J43*(1-J44) -> 1417.08 | K45: =K43*(1-K44) -> 1862.925
B47: Reinvestment | F47: =SUM(F40:F41) -> 735.92 | G47: =SUM(G40:G41) -> 648.94 | H47: =SUM(H40:H41) -> 357.88 | I47: =SUM(I40:I41) -> 867.61 | J47: =SUM(J40:J41) -> 980.45 | K47: =SUM(K40:K41) -> 916.96
B49: Reinvestment Rate | F49: =F47/F45 -> 0.68351491 | G49: =G47/G45 -> 0.92429745 | H49: =H47/H45 -> 0.37042155 | I49: =I47/I45 -> 0.77413512 | J49: =J47/J45 -> 0.69188049 | K49: =K47/K45 -> 0.4922152
J51: 5 Year Average | K51: =AVERAGE(G49:K49) -> 0.65058996
J52: 5 Year Median | K52: =MEDIAN(G49:K49) -> 0.69188049
A54: # | B54: Calculation of Growth Rate | F54: ='Raw FS'!I$2 -> 44256 | G54: ='Raw FS'!J$2 -> 44621 | H54: ='Raw FS'!K$2 -> 44986 | I54: ='Raw FS'!L$2 -> 45352 | J54: ='Raw FS'!M$2 -> 45717 | K54: ='Raw FS'!N$2 -> 46082
B56: Reinvestment Rate | F56: =F49 -> 0.68351491 | G56: =G49 -> 0.92429745 | H56: =H49 -> 0.37042155 | I56: =I49 -> 0.77413512 | J56: =J49 -> 0.69188049 | K56: =K49 -> 0.4922152
...

Sheet Relative Comps Valuation
B2: Comparable Company Valuation
C4: Market Data | I4: Financials | M4: Valuation
B5: Company | C5: Share Price | D5: Shares O/s | E5: Equity Value | F5: Net Debt | G5: Enterprise Value | I5: Revenue | J5: EBITDA | K5: Net Income | M5: EV/Revenue | N5: EV/EBITDA | O5: P/E
B7: ='Raw comps data'!C9 -> Persistent Systems | C7: ='Raw comps data'!D9 -> 5654 | D7: ='Raw comps data'!E9 -> 15.75 | E7: ='Raw comps data'!F9 -> 89050.5 | F7: ='Raw comps data'!I9 -> -740.8 | G7: ='Raw comps data'!J9 -> 88309.7 | I7: ='Raw comps data'!K9 -> 15718 | J7: ='Raw comps data'!L9 -> 2881.1094 | K7: ='Raw comps data'!M9 -> 1923 | M7: =G7/I7 -> 5.6183802 | N7: =G7/J7 -> 30.651283 | O7: =E7/K7 -> 46.308112
B8: ='Raw comps data'!C8 -> Oracle Fin.Serv. | C8: ='Raw comps data'!D8 -> 11799 | D8: ='Raw comps data'!E8 -> 8.71 | E8: ='Raw comps data'!F8 -> 102769.29 | F8: ='Raw comps data'!I8 -> -6000 | G8: ='Raw comps data'!J8 -> 96769.29 | I8: ='Raw comps data'!K8 -> 8945 | J8: ='Raw comps data'!L8 -> 4025.25 | K8: ='Raw comps data'!M8 -> 3413 | M8: =G8/I8 -> 10.818255 | N8: =G8/J8 -> 24.040566 | O8: =E8/K8 -> 30.111131
B9: ='Raw comps data'!C10 -> Coforge | C9: ='Raw comps data'!D10 -> 1889.1 | D9: ='Raw comps data'!E10 -> 44.29 | E9: ='Raw comps data'!F10 -> 83668.239 | F9: ='Raw comps data'!I10 -> -1772.2 | G9: ='Raw comps data'!J10 -> 81896.039 | I9: ='Raw comps data'!K10 -> 18195 | J9: ='Raw comps data'!L10 -> 3457.05 | K9: ='Raw comps data'!M10 -> 1920 | M9: =G9/I9 -> 4.5010189 | N9: =G9/J9 -> 23.689573 | O9: =E9/K9 -> 43.577208
B10: ='Raw comps data'!C11 -> Mphasis | C10: ='Raw comps data'!D11 -> 2394.9 | D10: ='Raw comps data'!E11 -> 19.09 | E10: ='Raw comps data'!F11 -> 45718.641 | F10: ='Raw comps data'!I11 -> 819.68 | G10: ='Raw comps data'!J11 -> 46538.321 | I10: ='Raw comps data'!K11 -> 16531 | J10: ='Raw comps data'!L11 -> 2644.96 | K10: ='Raw comps data'!M11 -> 1910 | M10: =G10/I10 -> 2.8152151 | N10: =G10/J10 -> 17.595094 | O10: =E10/K10 -> 23.936461
B11: ='Raw comps data'!C12 -> Hexaware Tech. | C11: ='Raw comps data'!D12 -> 548.3 | D11: ='Raw comps data'!E12 -> 61.1 | E11: ='Raw comps data'!F12 -> 33501.13 | F11: ='Raw comps data'!I12 -> -870 | G11: ='Raw comps data'!J12 -> 32631.13 | I11: ='Raw comps data'!K12 -> 15380 | J11: ='Raw comps data'!L12 -> 2460.8 | K11: ='Raw comps data'!M12 -> 1320.8 | M11: =G11/I11 -> 2.1216599 | N11: =G11/J11 -> 13.260375 | O11: =E11/K11 -> 25.364272
B12: ='Raw comps data'!C13 -> Tata Elxsi | C12: ='Raw comps data'!D13 -> 3633.8 | D12: ='Raw comps data'!E13 -> 6.23 | E12: ='Raw comps data'!F13 -> 22638.574 | F12: ='Raw comps data'!I13 -> -650 | G12: ='Raw comps data'!J13 -> 21988.574 | I12: ='Raw comps data'!K13 -> 3886 | J12: ='Raw comps data'!L13 -> 816.06 | K12: ='Raw comps data'!M13 -> 655 | M12: =G12/I12 -> 5.6584081 | N12: =G12/J12 -> 26.944801 | O12: =E12/K12 -> 34.562708
B13: ='Raw comps data'!C14 -> Firstsource Solutions | C13: ='Raw comps data'!D14 -> 263.8 | D13: ='Raw comps data'!E14 -> 72.14 | E13: ='Raw comps data'!F14 -> 19030.532 | F13: ='Raw comps data'!I14 -> 300 | G13: ='Raw comps data'!J14 -> 19330.532 | I13: ='Raw comps data'!K14 -> 11000 | J13: ='Raw comps data'!L14 -> 1100 | K13: ='Raw comps data'!M14 -> 550 | M13: =G13/I13 -> 1.7573211 | N13: =G13/J13 -> 17.573211 | O13: =E13/K13 -> 34.600967
B14: ='Raw comps data'!C15 -> eClerx Services | C14: ='Raw comps data'!D15 -> 1758 | D14: ='Raw comps data'!E15 -> 9.47 | E14: ='Raw comps data'!F15 -> 16648.26 | F14: ='Raw comps data'!I15 -> -750 | G14: ='Raw comps data'!J15 -> 15898.26 | I14: ='Raw comps data'!K15 -> 4680 | J14: ='Raw comps data'!L15 -> 1123.2 | K14: ='Raw comps data'!M15 -> 657.2 | M14: =G14/I14 -> 3.3970641 | N14: =G14/J14 -> 14.154434 | O14: =E14/K14 -> 25.332106
B15: ='Raw comps data'!C16 -> KPIT Technologies | C15: ='Raw comps data'!D16 -> 582.35 | D15: ='Raw comps data'!E16 -> 27.41 | E15: ='Raw comps data'!F16 -> 15962.213 | F15: ='Raw comps data'!I16 -> -400 | G15: ='Raw comps data'!J16 -> 15562.213 | I15: ='Raw comps data'!K16 -> 6700 | J15: ='Raw comps data'!L16 -> 1273 | K15: ='Raw comps data'!M16 -> 466 | M15: =G15/I15 -> 2.3227184 | N15: =G15/J15 -> 12.224834 | O15: =E15/K15 -> 34.253677
B16: ='Raw comps data'!C17 -> Fractal Analytics | C16: ='Raw comps data'!D17 -> 844.55 | D16: ='Raw comps data'!E17 -> 17.2 | E16: ='Raw comps data'!F17 -> 14526.26 | F16: ='Raw comps data'!I17 -> -750 | G16: ='Raw comps data'!J17 -> 13776.26 | I16: ='Raw comps data'!K17 -> 3650 | J16: ='Raw comps data'!L17 -> 547.5 | K16: ='Raw comps data'!M17 -> 289.2 | M16: =G16/I16 -> 3.7743178 | N16: =G16/J16 -> 25.162119 | O16: =E16/K16 -> 50.229115
B18: High | M18: =MAX(M8:M16) -> 10.818255 | N18: =MAX(N8:N16) -> 26.944801 | O18: =MAX(O8:O16) -> 50.229115
B19: 75th Percentile | M19: =QUARTILE(M8:M16,3) -> 4.5010189 | N19: =QUARTILE(N8:N16,3) -> 24.040566 | O19: =QUARTILE(O8:O16,3) -> 34.600967
B20: Average | M20: =AVERAGE(M8:M16) -> 4.1295532 | N20: =AVERAGE(N8:N16) -> 19.405001 | O20: =AVERAGE(O8:O16) -> 33.551961
B21: Median | M21: =MEDIAN(M8:M16) -> 3.3970641 | N21: =MEDIAN(N8:N16) -> 17.595094 | O21: =MEDIAN(O8:O16) -> 34.253677
B22: 25th Percentile | M22: =QUARTILE(M8:M16,1) -> 2.3227184 | N22: =QUARTILE(N8:N16,1) -> 14.154434 | O22: =QUARTILE(O8:O16,1) -> 25.364272
B23: Low | M23: =MIN(M8:M16) -> 1.7573211 | N23: =MIN(N8:N16) -> 12.224834 | O23: =MIN(O8:O16) -> 23.936461
B25: Persistent Systems Comparable Valuation | M25: EV/Revenue | N25: EV/EBITDA | O25: P/E
B27: Implied Enterprise Value | M27: =M21*I7 -> 53395.054 | N27: =N21*J7 -> 50693.392 | O27: =O29+O28 -> 65129.021
B28: Net Debt | M28: =$F$7 -> -740.8 | N28: =$F$7 -> -740.8 | O28: =$F$7 -> -740.8
B29: Implied Market Value | M29: =M27-M28 -> 54135.854 | N29: =N27-N28 -> 51434.192 | O29: =O21*K7 -> 65869.821
B30: Shares Outstanding | M30: =$D$7 -> 15.75 | N30: =$D$7 -> 15.75 | O30: =$D$7 -> 15.75
B31: Implies Value per Share | M31: =M29/M30 -> 3437.1971 | N31: =N29/N30 -> 3265.663 | O31: =O29/O30 -> 4182.2109
B32: Undervalued/Overvalued | M32: =IF(M31>$C$8,"Undervalued","Overvalued") -> Overvalued | N32: =IF(N31>$C$8,"Undervalued","Overvalued") -> Overvalued | O32: =IF(O31>$C$8,"Undervalued","Overvalued") -> Overvalued

Sheet Football Field Analysis
L2: Football Field Analysis - Data
M3: OpenLow | N3: Low | O3: OpenHigh | P3: High
L4: Comps | M4: =N4 -> 3265.663 | N4: ='Relative Comps Valuation'!N31 -> 3265.663 | O4: =P4 -> 3437.1971 | P4: ='Relative Comps Valuation'!M31 -> 3437.1971
L5: DCF Bear | M5: =N5 -> 756.61585 | N5: =DCF!J19 -> 756.61585 | O5: =P5 -> 1097.6532 | P5: =DCF!J23 -> 1097.6532
L6: DCF Base | M6: =N6 -> 877.10497 | N6: =DCF!H19 -> 877.10497 | O6: =P6 -> 1631.4001 | P6: =DCF!H23 -> 1631.4001
L7: DCF Bull | M7: =N7 -> 1097.6532 | N7: =DCF!F19 -> 1097.6532 | O7: =P7 -> 4779.2517 | P7: =DCF!F23 -> 4779.2517
L8: 52W H/L | M8: =N8 -> 4300 | N8: 4300 | O8: =P8 -> 6788 | P8: 6788

Sheet Raw Beta Peers
B2: Raw data for Beta -> screener & topstock research
B3: S.No. | C3: Name | D3: CMP Rs. | E3: Mar Cap Rs.Cr. | F3: Debt Rs.Cr. | G3: Debt / Eq | H3: Weekly - Two Year Range
B4: 1 | C4: LTM | D4: 4464 | E4: 131820.63 | F4: 2310 | G4: 0.1 | H4: 1.16
B5: 2 | C5: Oracle Fin. Serv. | D5: 11855 | E5: 103353.1 | F5: 32.5 | G5: 0 | H5: 1.02
B6: 3 | C6: Persistent Systems | D6: 5654 | E6: 89040.54 | F6: 477.45 | G6: 0.06 | H6: 1.09
B7: 4 | C7: Coforge | D7: 1901.8 | E7: 84234.62 | F7: 727.8 | G7: 0.08 | H7: 1.14
B8: 5 | C8: Mphasis | D8: 2413.6 | E8: 46088.08 | F8: 2619.68 | G8: 0.24 | H8: 1.32

Sheet Raw FS
B2: Bal Sheet Source screener | C2: 42064 | D2: 42430 | E2: 42795 | F2: 43160 | G2: 43525 | H2: 43891 | I2: 44256 | J2: 44621 | K2: 44986 | L2: 45352 | M2: 45717 | N2: 46082
B4: Equity Capital | C4: 80 | D4: 80 | E4: 80 | F4: 80 | G4: 79.12 | H4: 76.43 | I4: 76.43 | J4: 76.43 | K4: 76.43 | L4: 77.03 | M4: 77.93 | N4: 78.88
B5: Reserves | C5: 780 | D5: 850 | E5: 1819.26 | F5: 2047.2 | G5: 2265.56 | H5: 2309.33 | I5: 2719.24 | J5: 3291.8 | K5: 3888.65 | L5: 4880.68 | M5: 6241.14 | N5: 7758.98
B6: Borrowings - | C6: =SUM(C7:C10) -> 3 | D6: =SUM(D7:D10) -> 3 | E6: =SUM(E7:E10) -> 2.73 | F6: =SUM(F7:F10) -> 2.19 | G6: =SUM(G7:G10) -> 1.67 | H6: =SUM(H7:H10) -> 71.38 | I6: =SUM(I7:I10) -> 98.45 | J6: =SUM(J7:J10) -> 578.21 | ... N6: =SUM(N7:N10) -> 477.45
B7: Long term Borrowings | C7: 0.45 | D7: 0.45 | E7: 0.41 | F7: 0.33 | G7: 0.25 | H7: 10.71 | I7: 14.77 | J7: 86.73 | K7: 98.31 | L7: 67.67 | M7: 46.63 | N7: 71.62
B8: Short term Borrowings | C8: 0.45 | D8: 0.45 | E8: 0.41 | F8: 0.33 | G8: 0.25 | H8: 10.71 | I8: 14.77 | J8: 86.73 | K8: 98.31 | L8: 67.67 | M8: 46.63 | N8: 71.62
B9: Lease Liabilities | C9: 1.95 | D9: 1.95 | E9: 1.77 | F9: 1.42 | G9: 1.09 | H9: 46.39 | I9: 63.99 | J9: 375.84 | K9: 425.99 | L9: 293.23 | M9: 202.08 | N9: 310.34
B10: Other Borrowings | C10: 0.15 | D10: 0.15 | E10: 0.14 | F10: 0.11 | G10: 0.08 | H10: 3.57 | I10: 4.92 | J10: 28.91 | K10: 32.77 | L10: 22.56 | M10: 15.54 | N10: 23.87
B11: Other Liabilities - | C11: =SUM(C12:C15) -> 280 | D11: =SUM(D12:D15) -> 350 | E11: =SUM(E12:E15) -> 433.34 | F11: =SUM(F12:F15) -> 514.37 | G11: =SUM(G12:G15) -> 509.26 | H11: =SUM(H12:H15) -> 635.02 | I11: =SUM(I12:I15) -> 771.42 | J11: =SUM(J12:J15) -> 1472.65 | ... N11: =SUM(N12:N15) -> 3028.61
B12: Non controlling int | C12: 0 | D12: 0 | E12: 0 | F12: 0 | G12: 0 | H12: 0 | I12: 0 | J12: 0 | K12: 0 | L12: 0 | M12: 0 | N12: 0
B13: Trade Payables | C13: 106.4 | D13: 133 | E13: 164.67 | F13: 195.46 | G13: 193.52 | H13: 241.31 | I13: 293.14 | J13: 559.61 | K13: 759.51 | L13: 758.71 | M13: 794.8 | N13: 1150.87
B14: Advance from Customers | C14: 39.2 | D14: 49 | E14: 60.67 | F14: 72.01 | G14: 71.3 | H14: 88.9 | I14: 108 | J14: 206.17 | K14: 279.82 | L14: 279.53 | M14: 292.82 | N14: 424.01
B15: Other liability items | C15: 134.4 | D15: 168 | E15: 208 | F15: 246.9 | G15: 244.44 | H15: 304.81 | I15: 370.28 | J15: 706.87 | K15: 959.38 | L15: 958.37 | M15: 1003.96 | N15: 1453.73
B16: Total Liabilities | C16: =C4+C5+C6+C11 -> 1143 | D16: =D4+D5+D6+D11 -> 1283 | E16: =E4+E5+E6+E11 -> 2335.33 | F16: =F4+F5+F6+F11 -> 2643.76 | G16: =G4+G5+G6+G11 -> 2855.61 | H16: =H4+H5+H6+H11 -> 3092.16 | I16: =I4+I5+I6+I11 -> 3665.54 | J16: =J4+J5+J6+J11 -> 5419.09 | ... N16: =N4+N5+N6+N11 -> 11343.92
B18: Fixed Assets - | C18: =C27-C28 -> 220 | D18: =D27-D28 -> 379.99 | E18: =E27-E28 -> 535.95 | F18: =F27-F28 -> 512.15 | G18: =G27-G28 -> 400.8 | H18: =H27-H28 -> 431.53 | I18: =I27-I28 -> 456.94 | J18: =J27-J28 -> 1533.57 | ... N18: =N27-N28 -> 2855.98
B19: Land | C19: 12 | D19: 20.73 | E19: 29.23 | F19: 27.94 | G19: 21.86 | H19: 23.54 | I19: 24.92 | J19: 83.65 | K19: 127.71 | L19: 121.17 | M19: 138.6 | N19: 155.78
B20: Building | C20: 128 | D20: 221.09 | E20: 311.83 | F20: 297.98 | G20: 233.19 | H20: 251.07 | I20: 265.86 | J20: 892.26 | K20: 1362.23 | L20: 1292.49 | M20: 1478.45 | N20: 1661.66
B21: Plant Machinery | C21: 112 | D21: 193.45 | E21: 272.85 | F21: 260.73 | G21: 204.04 | H21: 219.69 | I21: 232.62 | J21: 780.73 | K21: 1191.95 | L21: 1130.93 | M21: 1293.64 | N21: 1453.95
B22: Equipments | C22: 32 | D22: 55.27 | E22: 77.96 | F22: 74.49 | G22: 58.3 | H22: 62.77 | I22: 66.46 | J22: 223.06 | K22: 340.56 | L22: 323.12 | M22: 369.61 | N22: 415.42
B23: Furniture n fittings | C23: 36 | D23: 62.18 | E23: 87.7 | F23: 83.81 | G23: 65.58 | H23: 70.61 | I23: 74.77 | J23: 250.95 | K23: 383.13 | L23: 363.51 | M23: 415.81 | N23: 467.34
B24: Vehicles | C24: 4 | D24: 6.91 | E24: 9.74 | F24: 9.31 | G24: 7.29 | H24: 7.85 | I24: 8.31 | J24: 27.88 | K24: 42.57 | L24: 40.39 | M24: 46.2 | N24: 51.93
B25: Intangible Assets | C25: 48 | D25: 82.91 | E25: 116.94 | F25: 111.74 | G25: 87.45 | H25: 94.15 | I25: 99.7 | J25: 334.6 | K25: 510.84 | L25: 484.68 | M25: 554.42 | N25: 623.12
B26: Other fixed assets | C26: 28 | D26: 48.36 | E26: 68.21 | F26: 65.18 | G26: 51.01 | H26: 54.92 | I26: 58.16 | J26: 195.18 | K26: 297.99 | L26: 282.73 | M26: 323.41 | N26: 363.49
B27: Gross Block | C27: =SUM(C19:C26) -> 400 | D27: =SUM(D19:D26) -> 690.9 | E27: =SUM(E19:E26) -> 974.46 | F27: =SUM(F19:F26) -> 931.18 | G27: =SUM(G19:G26) -> 728.72 | H27: =SUM(H19:H26) -> 784.6 | I27: =SUM(I19:I26) -> 830.8 | J27: =SUM(J19:J26) -> 2788.31 | ... N27: =SUM(N19:N26) -> 5192.69
B28: Accumulated Depreciation | C28: 180 | D28: 310.91 | E28: 438.51 | F28: 419.03 | G28: 327.92 | H28: 353.07 | I28: 373.86 | J28: 1254.74 | K28: 1915.63 | L28: 1817.57 | M28: 2079.07 | N28: 2336.71
B31: CWIP | C31: 15 | D31: 20 | E31: 28.96 | F31: 5.24 | G31: 31.56 | H31: 30.34 | I31: 12.18 | J31: 107.12 | K31: 16.14 | L31: 33.53 | M31: 77.36 | N31: 37.58
B32: Investments | C32: 420 | D32: 520 | E32: 683.91 | F32: 879.74 | G32: 764.12 | H32: 978.57 | I32: 999.62 | J32: 822.46 | K32: 639.57 | L32: 826.57 | M32: 980.32 | N32: 1614.77
B34: Other Assets - | C34: =SUM(C35:C39) -> 488 | D34: =SUM(D35:D39) -> 363 | E34: =SUM(E35:E39) -> 1086.48 | F34: =SUM(F35:F39) -> 1246.64 | G34: =SUM(G35:G39) -> 1659.13 | H34: =SUM(H35:H39) -> 1651.72 | I34: =SUM(I35:I39) -> 2196.79 | J34: =SUM(J35:J39) -> 2955.95 | ... N34: =SUM(N35:N39) -> 6835.59
B35: Inventories | C35: 0 | D35: 0 | E35: 0 | F35: 0 | G35: 0 | H35: 0 | I35: 0 | J35: 0 | K35: 0 | L35: 0 | M35: 0 | N35: 0
B36: Trade receivables + | C36: 220 | D36: 250 | E36: 475.38 | F36: 484.74 | G36: 492.3 | H36: 592.2 | I36: 570.9 | J36: 948.43 | K36: 1570.46 | L36: 1676.11 | M36: 2679.17 | N36: 3334.39
B37: Cash Equivalents | C37: 90 | D37: 95 | E37: 150.96 | F37: 241.4 | G37: 672.88 | H37: 457.22 | I37: 980.9 | J37: 914.46 | K37: 903.28 | L37: 1022.89 | M37: 1025.47 | N37: 1218.25
B38: Loans n Advances | C38: 21.36 | D38: 2.16 | E38: 55.22 | F38: 62.46 | G38: 59.27 | H38: 72.28 | I38: 77.4 | J38: 131.17 | K38: 137.8 | L38: 194.99 | M38: 170.18 | N38: 273.95
B39: Other asset items | C39: 156.64 | D39: 15.84 | E39: 404.92 | F39: 458.04 | G39: 434.68 | H39: 530.02 | I39: 567.59 | J39: 961.89 | K39: 1010.57 | L39: 1429.89 | M39: 1247.97 | N39: 2009
B40: Total Assets | C40: =C18+C31+C32+C34 -> 1143 | D40: =D18+D31+D32+D34 -> 1282.99 | E40: =E18+E31+E32+E34 -> 2335.3 | F40: =F18+F31+F32+F34 -> 2643.77 | G40: =G18+G31+G32+G34 -> 2855.61 | H40: =H18+H31+H32+H34 -> 3092.16 | I40: =I18+I31+I32+I34 -> 3665.53 | J40: =J18+J31+J32+J34 -> 5419.1 | ... N40: =N18+N31+N32+N34 -> 11343.92
B43: Cash Flow Source screener | C43: 42064 | D43: 42430 | E43: 42795 | F43: 43160 | G43: 43525 | H43: 43891 | I43: 44256 | J43: 44621 | K43: 44986 | L43: 45352 | M43: 45717 | N43: 46082
B44: Cash from Operating Activity - | C44: =C45+C50+C51 -> 312 | D44: =D45+D50+D51 -> 254 | E44: =E45+E50+E51 -> 286.41 | F44: =F45+F50+F51 -> 421.19 | G44: =G45+G50+G51 -> 432.31 | H44: =H45+H50+H51 -> 351.59 | I44: =I45+I50+I51 -> 735.93 | J44: =J45+J50+J51 -> 844.99 | ... N44: =N45+N50+N51 -> 1767.13
B45: Profit from operations | C45: 361.4 | D45: 441.7 | E45: 549.79 | F45: 587.83 | G45: 643.9 | H45: 624.64 | I45: 790.79 | J45: 1102.13 | K45: 1560.09 | L45: 1803.7 | M45: 2196.35 | N45: 2886.85
B46: Receivables | C46: 0 | D46: -30 | E46: -225.38 | F46: -9.36 | G46: -7.56 | H46: -99.9 | I46: 21.3 | J46: -377.53 | K46: -622.03 | L46: -105.65 | M46: -1003.06 | N46: -655.22
B47: Inventory | C47: 0 | D47: 0 | E47: 0 | F47: 0 | G47: 0 | H47: 0 | I47: 0 | J47: 0 | K47: 0 | L47: 0 | M47: 0 | N47: 0
B48: Payables | C48: 0 | D48: 26.6 | E48: 31.67 | F48: 30.8 | G48: -1.95 | H48: 47.8 | I48: 51.83 | J48: 266.47 | K48: 199.9 | L48: -0.79 | M48: 36.09 | N48: 356.07
...

Sheet Raw comps data
B1: S.No. | C1: Name | D1: CMP Rs. | E1: No. Eq. Shares Cr. | F1: Market Cap | G1: Debt Rs.Cr. | H1: Cash End Rs.Cr. | I1: Net Debt | J1: EV | K1: Sales Rs.Cr. | L1: EBITDA | M1: NP 12M Rs.Cr. | N1: OPM %
B2: 1 | C2: TCS | D2: 2258.9 | E2: 361.81 | F2: =D2*E2 -> 817292.61 | G2: 100 | H2: 45000 | I2: =G2-H2 -> -44900 | J2: =F2+I2 -> 772392.61 | K2: 289100 | L2: =K2*N2 -> 80948 | M2: 53680 | N2: 0.28
B3: 2 | C3: Infosys | D3: 1111.45 | E3: 405.81 | F3: =D3*E3 -> 451037.52 | G3: 1500 | H3: 15000 | I3: =G3-H3 -> -13500 | J3: =F3+I3 -> 437537.52 | K3: 192844 | L3: =K3*N3 -> 48211 | M3: 31100 | N3: 0.25
B4: 3 | C4: HCL Technologies | D4: 1288.45 | E4: 271.37 | F4: =D4*E4 -> 349646.68 | G4: 5000 | H4: 12000 | I4: =G4-H4 -> -7000 | J4: =F4+I4 -> 342646.68 | K4: 138316 | L4: =K4*N4 -> 33195.84 | M4: 18504 | N4: 0.24
B5: 4 | C5: Wipro | D5: 177.7 | E5: 990.45 | F5: =D5*E5 -> 176002.96 | G5: 8000 | H5: 15000 | I5: =G5-H5 -> -7000 | J5: =F5+I5 -> 169002.96 | K5: 97914.4 | L5: =K5*N5 -> 20562.024 | M5: 13425.2 | N5: 0.21
B6: 5 | C6: Tech Mahindra | D6: 1590.5 | E6: 98.01 | F6: =D6*E6 -> 155884.9 | G6: 2000 | H6: 6000 | I6: =G6-H6 -> -4000 | J6: =F6+I6 -> 151884.9 | K6: 62847.6 | L6: =K6*N6 -> 8798.664 | M6: 5945.2 | N6: 0.14
B7: 6 | C7: LTIMindtree | D7: 4505.7 | E7: 29.66 | F7: =D7*E7 -> 133639.06 | G7: 500 | H7: 5000 | I7: =G7-H7 -> -4500 | J7: =F7+I7 -> 129139.06 | K7: 46432 | L7: =K7*N7 -> 8822.08 | M7: 5874.4 | N7: 0.19
B8: 7 | C8: Oracle Fin.Serv. | D8: 11799 | E8: 8.71 | F8: =D8*E8 -> 102769.29 | G8: 0 | H8: 6000 | I8: =G8-H8 -> -6000 | J8: =F8+I8 -> 96769.29 | K8: 8945 | L8: =K8*N8 -> 4025.25 | M8: 3413 | N8: 0.45
B9: 8 | C9: Persistent Systems | D9: 5654 | E9: 15.75 | F9: =D9*E9 -> 89050.5 | G9: 477.45 | H9: 1218.25 | I9: =G9-H9 -> -740.8 | J9: =F9+I9 -> 88309.7 | K9: 15718 | L9: =K9*N9 -> 2881.1094 | M9: 1923 | N9: 0.1833
B10: 9 | C10: Coforge | D10: 1889.1 | E10: 44.29 | F10: =D10*E10 -> 83668.239 | G10: 727.8 | H10: 2500 | I10: =G10-H10 -> -1772.2 | J10: =F10+I10 -> 81896.039 | K10: 18195 | L10: =K10*N10 -> 3457.05 | M10: 1920 | N10: 0.19
B11: 10 | C11: Mphasis | D11: 2394.9 | E11: 19.09 | F11: =D11*E11 -> 45718.641 | G11: 2619.68 | H11: 1800 | I11: =G11-H11 -> 819.68 | J11: =F11+I11 -> 46538.321 | K11: 16531 | L11: =K11*N11 -> 2644.96 | M11: 1910 | N11: 0.16
B12: 11 | C12: Hexaware Tech. | D12: 548.3 | E12: 61.1 | F12: =D12*E12 -> 33501.13 | G12: 600 | H12: 1470 | I12: =G12-H12 -> -870 | J12: =F12+I12 -> 32631.13 | K12: 15380 | L12: =K12*N12 -> 2460.8 | M12: 1320.8 | N12: 0.16
B13: 12 | C13: Tata Elxsi | D13: 3633.8 | E13: 6.23 | F13: =D13*E13 -> 22638.574 | G13: 50 | H13: 700 | I13: =G13-H13 -> -650 | J13: =F13+I13 -> 21988.574 | K13: 3886 | L13: =K13*N13 -> 816.06 | M13: 655 | N13: 0.21
... B31: 30 | C31: Nucleus Software Exports | D31: 950 | E31: 3.05 | F31: =D31*E31 -> 2897.5 | G31: 20 | H31: 200 | I31: =G31-H31 -> -180 | J31: =F31+I31 -> 2717.5 | K31: 550 | L31: =K31*N31 -> 110 | M31: 110 | N31: 0.2

Sheet Data Sheet
A1: COMPANY NAME | B1: PERSISTENT SYSTEMS LTD | E1: =IF(B2<>B3, "A NEW VERSION OF THE WORKSHEET IS AVAILABLE", "")
A2: LATEST VERSION | B2: 2.1 | E2: PLEASE DO NOT MAKE ANY CHANGES TO THIS SHEET
A3: CURRENT VERSION | B3: 2.1
A5: META
A6: Number of shares | B6: =IF(B9>0, B9/B8, 0) -> 15.748238
A7: Face Value | B7: 5
A8: Current Price | B8: 5654
A9: Market Capitalization | B9: 89040.54
A15: PROFIT & LOSS | B15: =B26+B34 -> 698.81 | K15: =K17-K18-K20-K21-K22-K23-K19 -> 2945.85
A16: Report Date | B16: 42825 | C16: 43190 | D16: 43555 | E16: 43921 | F16: 44286 | G16: 44651 | H16: 45016 | I16: 45382 | J16: 45747 | K16: 46112
A17: Sales | B17: 2878.44 | C17: 3033.7 | D17: 3365.94 | E17: 3565.81 | F17: 4187.89 | G17: 5710.75 | H17: 8350.59 | I17: 9821.59 | J17: 11938.72 | K17: 14748.45
A18: Raw Material Cost
A19: Change in Inventory
A20: Power and Fuel | B20: 13.87 | C20: 10.45 | D20: 10.95 | E20: 11.49 | F20: 8.26 | G20: 7.61 | H20: 12.03 | I20: 14.1 | J20: 13.15 | K20: 13.72
A21: Other Mfr. Exp | B21: 332.2 | C21: 446.07 | D21: 535.05 | E21: 605.59 | F21: 784.24 | G21: 1039.71 | H21: 1467.87 | I21: 1793 | J21: 2578.77 | K21: 3305.96
A22: Employee Cost | B22: 1766.31 | C22: 1833.01 | D22: 1926.9 | E22: 2157.78 | F22: 2517.31 | G22: 3462.14 | H22: 4973.17 | I22: 5965.2 | J22: 6878.19 | K22: 7955.59
A23: Selling and admin | B23: 254.56 | C23: 238.89 | D23: 261.3 | E23: 215.02 | F23: 134.7 | G23: 180.64 | H23: 300.58 | I23: 335.83 | J23: 422.89 | K23: 527.33
A24: Other Expenses | B24: 46.16 | C24: 36.55 | D24: 75.5 | E24: 83.09 | F24: 60.37 | G24: 62.48 | H24: 77.82 | I24: 37.77 | J24: -12.48 | K24: 149.98
A25: Other Income | B25: 84.44 | C25: 119.1 | D25: 87.66 | E25: 131.79 | F25: 107.77 | G25: 143.96 | H25: 40.97 | I25: 128.02 | J25: 138.15 | K25: 90.97
A26: Depreciation | B26: 149.02 | C26: 158.49 | D26: 157.25 | E26: 165.96 | F26: 175.55 | G26: 166.01 | H26: 271.9 | I26: 309.37 | J26: 306.91 | K26: 402.95
A27: Interest | B27: 0.09 | C27: 0.08 | D27: 0.31 | E27: 6.33 | F27: 5.79 | G27: 11.84 | H27: 47.34 | I27: 46.73 | J27: 67.13 | K27: 72.68
A28: Profit before tax | B28: 400.67 | C28: 429.26 | D28: 486.34 | E28: 452.34 | F28: 609.44 | G28: 924.28 | H28: 1240.85 | I28: 1447.61 | J28: 1822.31 | K28: 2411.21
A29: Tax | B29: 99.21 | C29: 106.17 | D29: 134.66 | E29: 112.06 | F29: 158.77 | G29: 233.89 | H29: 319.76 | I29: 354.11 | J29: 422.15 | K29: 546.1
A30: Net profit | B30: 301.47 | C30: 323.09 | D30: 351.68 | E30: 340.29 | F30: 450.68 | G30: 690.39 | H30: 921.09 | I30: 1093.49 | J30: 1400.16 | K30: 1865.12
A31: Dividend Amount | B31: 72 | C31: 80 | D31: 87.03 | E31: 91.72 | F31: 152.86 | G31: 236.93 | H31: 382.15 | I31: 400.56 | J31: 545.51 | K31: 631.04
A32: Effective Tax Rate | B32: =B29/B28 -> 0.24761025 | C32: =C29/C28 -> 0.24733262 | D32: =D29/D28 -> 0.27688448 | E32: =E29/E28 -> 0.24773401 | F32: =F29/F28 -> 0.26051785 | G32: =G29/G28 -> 0.25305102 | H32: =H29/H28 -> 0.25769432 | I32: =I29/I28 -> 0.24461699 | ... K32: =K29/K28 -> 0.2264838
A34: EBITDA | B34: =+B30+B29+B27+B26 -> 549.79 | C34: =+C30+C29+C27+C26 -> 587.83 | D34: =+D30+D29+D27+D26 -> 643.9 | E34: =+E30+E29+E27+E26 -> 624.64 | F34: =+F30+F29+F27+F26 -> 790.79 | G34: =+G30+G29+G27+G26 -> 1102.13 | H34: =+H30+H29+H27+H26 -> 1560.09 | I34: =+I30+I29+I27+I26 -> 1803.7 | ... K34: =+K30+K29+K27+K26 -> 2886.85
A40: Quarters
A41: Report Date | B41: 45382 | C41: 45473 | D41: 45565 | E41: 45657 | F41: 45747 | G41: 45838 | H41: 45930 | I41: 46022 | J41: 46112 | K41: 46203
A42: Sales | B42: 2590.53 | C42: 2737.17 | D42: 2897.15 | E42: 3062.28 | F42: 3242.11 | G42: 3333.59 | H42: 3580.72 | I42: 3778.21 | J42: 4055.94 | K42: 4303.23
A43: Expenses | B43: 2136.16 | C43: 2281.96 | D43: 2416.42 | E43: 2524.44 | F43: 2657.7 | G43: 2722 | H43: 2897.64 | I43: 3045.15 | J43: 3288.23 | K43: 3606.34
A44: Other Income | B44: 30.78 | C44: 30.64 | D44: 46.52 | E44: 42.63 | F44: 18.36 | G44: 54.66 | H44: 51.78 | I44: -48.53 | J44: 33.49 | K44: 70.64
A45: Depreciation | B45: 79.92 | C45: 71.2 | D45: 74.5 | E45: 82.12 | F45: 79.1 | G45: 93.78 | H45: 100.05 | I45: 100.58 | J45: 108.54 | K45: 115.29
A46: Interest | B46: 9.74 | C46: 14.11 | D46: 18.23 | E46: 16.32 | F46: 18.46 | G46: 17.06 | H46: 17.98 | I46: 18.96 | J46: 18.68 | K46: 29.14
A47: Profit before tax | B47: 395.49 | C47: 400.54 | D47: 434.52 | E47: 482.03 | F47: 505.21 | G47: 555.41 | H47: 616.83 | I47: 564.99 | J47: 673.98 | K47: 623.1
A48: Tax | B48: 80.17 | C48: 94.13 | D48: 109.52 | E48: 109.05 | F48: 109.44 | G48: 130.47 | H48: 145.36 | I48: 125.54 | J48: 144.72 | K48: 140.06
A49: Net profit | B49: 315.32 | C49: 306.42 | D49: 325 | E49: 372.99 | F49: 395.76 | G49: 424.94 | H49: 471.47 | I49: 439.45 | J49: 529.26 | K49: 483.04
A50: Operating Profit | B50: 454.37 | C50: 455.21 | D50: 480.73 | E50: 537.84 | F50: 584.41 | G50: 611.59 | H50: 683.08 | I50: 733.06 | J50: 767.71 | K50: 696.89
A51: EBITDA | B51: =B49+B48+B46+B45 -> 485.15 | C51: =C49+C48+C46+C45 -> 485.86 | D51: =D49+D48+D46+D45 -> 527.25 | E51: =E49+E48+E46+E45 -> 580.48 | F51: =F49+F48+F46+F45 -> 602.76 | G51: =G49+G48+G46+G45 -> 666.25 | H51: =H49+H48+H46+H45 -> 734.86 | I51: =I49+I48+I46+I45 -> 684.53 | ... K51: =K49+K48+K46+K45 -> 767.53
A55: BALANCE SHEET
...
